[D 180918 11:49:53 PassPort:9] debug msg
[I 180918 11:49:53 PassPort:10] info msg
[W 180918 11:49:53 PassPort:11] warning msg
[E 180918 11:49:53 PassPort:12] error msg
[I 180918 11:49:53 web:2162] 200 GET / (127.0.0.1) 39.96ms
[E 180918 11:49:54 web:1670] Uncaught exception GET /favicon.ico (127.0.0.1)
    HTTPServerRequest(protocol='http', host='127.0.0.1:8000', method='GET', uri='/favicon.ico', version='HTTP/1.1', remote_ip='127.0.0.1')
    Traceback (most recent call last):
      File "/usr/local/lib/python2.7/dist-packages/tornado/web.py", line 1592, in _execute
        result = yield result
      File "/usr/local/lib/python2.7/dist-packages/tornado/gen.py", line 1133, in run
        value = future.result()
      File "/usr/local/lib/python2.7/dist-packages/tornado/concurrent.py", line 261, in result
        raise_exc_info(self._exc_info)
      File "/usr/local/lib/python2.7/dist-packages/tornado/gen.py", line 326, in wrapper
        yielded = next(result)
      File "/usr/local/lib/python2.7/dist-packages/tornado/web.py", line 2463, in get
        absolute_path = self.get_absolute_path(self.root, self.path)
      File "/usr/local/lib/python2.7/dist-packages/tornado/web.py", line 2607, in get_absolute_path
        abspath = os.path.abspath(os.path.join(root, path))
      File "/usr/lib/python2.7/posixpath.py", line 73, in join
        path += '/' + b
    UnicodeDecodeError: 'ascii' codec can't decode byte 0xe7 in position 22: ordinal not in range(128)
[E 180918 11:49:54 web:2162] 500 GET /favicon.ico (127.0.0.1) 70.18ms
[D 180918 16:29:50 PassPort:9] debug msg
[I 180918 16:29:50 PassPort:10] info msg
[W 180918 16:29:50 PassPort:11] warning msg
[E 180918 16:29:50 PassPort:12] error msg
[I 180918 16:29:50 web:2162] 304 GET / (127.0.0.1) 34.59ms
[E 180918 16:29:51 web:1670] Uncaught exception GET /favicon.ico (127.0.0.1)
    HTTPServerRequest(protocol='http', host='127.0.0.1:8000', method='GET', uri='/favicon.ico', version='HTTP/1.1', remote_ip='127.0.0.1')
    Traceback (most recent call last):
      File "/usr/local/lib/python2.7/dist-packages/tornado/web.py", line 1592, in _execute
        result = yield result
      File "/usr/local/lib/python2.7/dist-packages/tornado/gen.py", line 1133, in run
        value = future.result()
      File "/usr/local/lib/python2.7/dist-packages/tornado/concurrent.py", line 261, in result
        raise_exc_info(self._exc_info)
      File "/usr/local/lib/python2.7/dist-packages/tornado/gen.py", line 326, in wrapper
        yielded = next(result)
      File "/usr/local/lib/python2.7/dist-packages/tornado/web.py", line 2463, in get
        absolute_path = self.get_absolute_path(self.root, self.path)
      File "/usr/local/lib/python2.7/dist-packages/tornado/web.py", line 2607, in get_absolute_path
        abspath = os.path.abspath(os.path.join(root, path))
      File "/usr/lib/python2.7/posixpath.py", line 73, in join
        path += '/' + b
    UnicodeDecodeError: 'ascii' codec can't decode byte 0xe7 in position 22: ordinal not in range(128)
[E 180918 16:29:51 web:2162] 500 GET /favicon.ico (127.0.0.1) 139.86ms
[W 180918 16:33:00 web:1667] 400 GET /api/imagecode?codeid=1234 (127.0.0.1): Missing argument pcodeid
[E 180918 16:33:00 web:1114] Uncaught exception in write_error
    Traceback (most recent call last):
      File "/usr/local/lib/python2.7/dist-packages/tornado/web.py", line 1112, in send_error
        self.write_error(status_code, **kwargs)
    TypeError: write_error() takes exactly 1 argument (3 given)
[W 180918 16:33:00 web:2162] 400 GET /api/imagecode?codeid=1234 (127.0.0.1) 11.44ms
[W 180918 16:33:03 web:1667] 400 GET /api/imagecode?codeid=1234 (127.0.0.1): Missing argument pcodeid
[E 180918 16:33:03 web:1114] Uncaught exception in write_error
    Traceback (most recent call last):
      File "/usr/local/lib/python2.7/dist-packages/tornado/web.py", line 1112, in send_error
        self.write_error(status_code, **kwargs)
    TypeError: write_error() takes exactly 1 argument (3 given)
[W 180918 16:33:03 web:2162] 400 GET /api/imagecode?codeid=1234 (127.0.0.1) 2.79ms
[W 180918 16:33:25 web:1667] 400 GET /api/imagecode?codeid=123 (127.0.0.1): Missing argument pcodeid
[E 180918 16:33:25 web:1114] Uncaught exception in write_error
    Traceback (most recent call last):
      File "/usr/local/lib/python2.7/dist-packages/tornado/web.py", line 1112, in send_error
        self.write_error(status_code, **kwargs)
    TypeError: write_error() takes exactly 1 argument (3 given)
[W 180918 16:33:25 web:2162] 400 GET /api/imagecode?codeid=123 (127.0.0.1) 2.15ms
[W 180918 16:34:40 web:1667] 400 GET /api/imagecode?codeid=123 (127.0.0.1): Missing argument pcodeid
[E 180918 16:34:40 web:1114] Uncaught exception in write_error
    Traceback (most recent call last):
      File "/usr/local/lib/python2.7/dist-packages/tornado/web.py", line 1112, in send_error
        self.write_error(status_code, **kwargs)
    TypeError: write_error() takes exactly 1 argument (3 given)
[W 180918 16:34:40 web:2162] 400 GET /api/imagecode?codeid=123 (127.0.0.1) 2.95ms
[E 180918 16:34:52 web:1670] Uncaught exception GET /api/imagecode?codeid=123&pcodeid= (127.0.0.1)
    HTTPServerRequest(protocol='http', host='127.0.0.1:8000', method='GET', uri='/api/imagecode?codeid=123&pcodeid=', version='HTTP/1.1', remote_ip='127.0.0.1')
    Traceback (most recent call last):
      File "/usr/local/lib/python2.7/dist-packages/tornado/web.py", line 1590, in _execute
        result = method(*self.path_args, **self.path_kwargs)
      File "/home/phantom/Desktop/爱家租房/handlers/VerifyCode.py", line 21, in get
        name,text,image = captcha.generate_captcha()
    AttributeError: 'module' object has no attribute 'generate_captcha'
[E 180918 16:34:52 web:1114] Uncaught exception in write_error
    Traceback (most recent call last):
      File "/usr/local/lib/python2.7/dist-packages/tornado/web.py", line 1112, in send_error
        self.write_error(status_code, **kwargs)
    TypeError: write_error() takes exactly 1 argument (3 given)
[E 180918 16:34:52 web:2162] 500 GET /api/imagecode?codeid=123&pcodeid= (127.0.0.1) 9.88ms
[I 180918 16:36:05 autoreload:199] /home/phantom/Desktop/爱家租房/handlers/VerifyCode.py modified; restarting server
[E 180918 16:36:12 web:1670] Uncaught exception GET /api/imagecode?codeid=123&pcodeid= (127.0.0.1)
    HTTPServerRequest(protocol='http', host='127.0.0.1:8000', method='GET', uri='/api/imagecode?codeid=123&pcodeid=', version='HTTP/1.1', remote_ip='127.0.0.1')
    Traceback (most recent call last):
      File "/usr/local/lib/python2.7/dist-packages/tornado/web.py", line 1590, in _execute
        result = method(*self.path_args, **self.path_kwargs)
      File "/home/phantom/Desktop/爱家租房/handlers/VerifyCode.py", line 21, in get
        name,text,image = captcha.generate_captcha()
    AttributeError: 'module' object has no attribute 'generate_captcha'
[E 180918 16:36:12 web:1114] Uncaught exception in write_error
    Traceback (most recent call last):
      File "/usr/local/lib/python2.7/dist-packages/tornado/web.py", line 1112, in send_error
        self.write_error(status_code, **kwargs)
    TypeError: write_error() takes exactly 1 argument (3 given)
[E 180918 16:36:12 web:2162] 500 GET /api/imagecode?codeid=123&pcodeid= (127.0.0.1) 6.77ms
[E 180918 16:36:15 web:1670] Uncaught exception GET /api/imagecode?codeid=123&pcodeid= (127.0.0.1)
    HTTPServerRequest(protocol='http', host='127.0.0.1:8000', method='GET', uri='/api/imagecode?codeid=123&pcodeid=', version='HTTP/1.1', remote_ip='127.0.0.1')
    Traceback (most recent call last):
      File "/usr/local/lib/python2.7/dist-packages/tornado/web.py", line 1590, in _execute
        result = method(*self.path_args, **self.path_kwargs)
      File "/home/phantom/Desktop/爱家租房/handlers/VerifyCode.py", line 21, in get
        name,text,image = captcha.generate_captcha()
    AttributeError: 'module' object has no attribute 'generate_captcha'
[E 180918 16:36:15 web:1114] Uncaught exception in write_error
    Traceback (most recent call last):
      File "/usr/local/lib/python2.7/dist-packages/tornado/web.py", line 1112, in send_error
        self.write_error(status_code, **kwargs)
    TypeError: write_error() takes exactly 1 argument (3 given)
[E 180918 16:36:15 web:2162] 500 GET /api/imagecode?codeid=123&pcodeid= (127.0.0.1) 3.62ms
[E 180918 16:37:47 web:1670] Uncaught exception GET /api/imagecode?codeid=123&pcodeid= (127.0.0.1)
    HTTPServerRequest(protocol='http', host='127.0.0.1:8000', method='GET', uri='/api/imagecode?codeid=123&pcodeid=', version='HTTP/1.1', remote_ip='127.0.0.1')
    Traceback (most recent call last):
      File "/usr/local/lib/python2.7/dist-packages/tornado/web.py", line 1590, in _execute
        result = method(*self.path_args, **self.path_kwargs)
      File "/home/phantom/Desktop/爱家租房/handlers/VerifyCode.py", line 21, in get
        name,text,image = captcha.generate_captcha()
    AttributeError: 'module' object has no attribute 'generate_captcha'
[E 180918 16:37:47 web:1114] Uncaught exception in write_error
    Traceback (most recent call last):
      File "/usr/local/lib/python2.7/dist-packages/tornado/web.py", line 1112, in send_error
        self.write_error(status_code, **kwargs)
    TypeError: write_error() takes exactly 1 argument (3 given)
[E 180918 16:37:47 web:2162] 500 GET /api/imagecode?codeid=123&pcodeid= (127.0.0.1) 4.28ms
[E 180918 16:37:49 web:1670] Uncaught exception GET /api/imagecode?codeid=123&pcodeid= (127.0.0.1)
    HTTPServerRequest(protocol='http', host='127.0.0.1:8000', method='GET', uri='/api/imagecode?codeid=123&pcodeid=', version='HTTP/1.1', remote_ip='127.0.0.1')
    Traceback (most recent call last):
      File "/usr/local/lib/python2.7/dist-packages/tornado/web.py", line 1590, in _execute
        result = method(*self.path_args, **self.path_kwargs)
      File "/home/phantom/Desktop/爱家租房/handlers/VerifyCode.py", line 21, in get
        name,text,image = captcha.generate_captcha()
    AttributeError: 'module' object has no attribute 'generate_captcha'
[E 180918 16:37:49 web:1114] Uncaught exception in write_error
    Traceback (most recent call last):
      File "/usr/local/lib/python2.7/dist-packages/tornado/web.py", line 1112, in send_error
        self.write_error(status_code, **kwargs)
    TypeError: write_error() takes exactly 1 argument (3 given)
[E 180918 16:37:49 web:2162] 500 GET /api/imagecode?codeid=123&pcodeid= (127.0.0.1) 4.23ms
[E 180918 16:37:51 web:1670] Uncaught exception GET /api/imagecode?codeid=123&pcodeid= (127.0.0.1)
    HTTPServerRequest(protocol='http', host='127.0.0.1:8000', method='GET', uri='/api/imagecode?codeid=123&pcodeid=', version='HTTP/1.1', remote_ip='127.0.0.1')
    Traceback (most recent call last):
      File "/usr/local/lib/python2.7/dist-packages/tornado/web.py", line 1590, in _execute
        result = method(*self.path_args, **self.path_kwargs)
      File "/home/phantom/Desktop/爱家租房/handlers/VerifyCode.py", line 21, in get
        name,text,image = captcha.generate_captcha()
    AttributeError: 'module' object has no attribute 'generate_captcha'
[E 180918 16:37:51 web:1114] Uncaught exception in write_error
    Traceback (most recent call last):
      File "/usr/local/lib/python2.7/dist-packages/tornado/web.py", line 1112, in send_error
        self.write_error(status_code, **kwargs)
    TypeError: write_error() takes exactly 1 argument (3 given)
[E 180918 16:37:51 web:2162] 500 GET /api/imagecode?codeid=123&pcodeid= (127.0.0.1) 6.64ms
[E 180918 16:37:52 web:1670] Uncaught exception GET /api/imagecode?codeid=123&pcodeid= (127.0.0.1)
    HTTPServerRequest(protocol='http', host='127.0.0.1:8000', method='GET', uri='/api/imagecode?codeid=123&pcodeid=', version='HTTP/1.1', remote_ip='127.0.0.1')
    Traceback (most recent call last):
      File "/usr/local/lib/python2.7/dist-packages/tornado/web.py", line 1590, in _execute
        result = method(*self.path_args, **self.path_kwargs)
      File "/home/phantom/Desktop/爱家租房/handlers/VerifyCode.py", line 21, in get
        name,text,image = captcha.generate_captcha()
    AttributeError: 'module' object has no attribute 'generate_captcha'
[E 180918 16:37:52 web:1114] Uncaught exception in write_error
    Traceback (most recent call last):
      File "/usr/local/lib/python2.7/dist-packages/tornado/web.py", line 1112, in send_error
        self.write_error(status_code, **kwargs)
    TypeError: write_error() takes exactly 1 argument (3 given)
[E 180918 16:37:52 web:2162] 500 GET /api/imagecode?codeid=123&pcodeid= (127.0.0.1) 3.35ms
[W 180918 16:42:36 web:2162] 404 GET /api (127.0.0.1) 1.38ms
[E 180918 16:42:36 web:1670] Uncaught exception GET /favicon.ico (127.0.0.1)
    HTTPServerRequest(protocol='http', host='127.0.0.1:8000', method='GET', uri='/favicon.ico', version='HTTP/1.1', remote_ip='127.0.0.1')
    Traceback (most recent call last):
      File "/usr/local/lib/python2.7/dist-packages/tornado/web.py", line 1592, in _execute
        result = yield result
      File "/usr/local/lib/python2.7/dist-packages/tornado/gen.py", line 1133, in run
        value = future.result()
      File "/usr/local/lib/python2.7/dist-packages/tornado/concurrent.py", line 261, in result
        raise_exc_info(self._exc_info)
      File "/usr/local/lib/python2.7/dist-packages/tornado/gen.py", line 326, in wrapper
        yielded = next(result)
      File "/usr/local/lib/python2.7/dist-packages/tornado/web.py", line 2463, in get
        absolute_path = self.get_absolute_path(self.root, self.path)
      File "/usr/local/lib/python2.7/dist-packages/tornado/web.py", line 2607, in get_absolute_path
        abspath = os.path.abspath(os.path.join(root, path))
      File "/usr/lib/python2.7/posixpath.py", line 73, in join
        path += '/' + b
    UnicodeDecodeError: 'ascii' codec can't decode byte 0xe7 in position 22: ordinal not in range(128)
[E 180918 16:42:36 web:2162] 500 GET /favicon.ico (127.0.0.1) 13.59ms
[D 180918 16:42:43 PassPort:9] debug msg
[I 180918 16:42:43 PassPort:10] info msg
[W 180918 16:42:43 PassPort:11] warning msg
[E 180918 16:42:43 PassPort:12] error msg
[I 180918 16:42:43 web:2162] 304 GET / (127.0.0.1) 21.61ms
[E 180918 16:42:43 web:1670] Uncaught exception GET /favicon.ico (127.0.0.1)
    HTTPServerRequest(protocol='http', host='127.0.0.1:8000', method='GET', uri='/favicon.ico', version='HTTP/1.1', remote_ip='127.0.0.1')
    Traceback (most recent call last):
      File "/usr/local/lib/python2.7/dist-packages/tornado/web.py", line 1592, in _execute
        result = yield result
      File "/usr/local/lib/python2.7/dist-packages/tornado/gen.py", line 1133, in run
        value = future.result()
      File "/usr/local/lib/python2.7/dist-packages/tornado/concurrent.py", line 261, in result
        raise_exc_info(self._exc_info)
      File "/usr/local/lib/python2.7/dist-packages/tornado/gen.py", line 326, in wrapper
        yielded = next(result)
      File "/usr/local/lib/python2.7/dist-packages/tornado/web.py", line 2463, in get
        absolute_path = self.get_absolute_path(self.root, self.path)
      File "/usr/local/lib/python2.7/dist-packages/tornado/web.py", line 2607, in get_absolute_path
        abspath = os.path.abspath(os.path.join(root, path))
      File "/usr/lib/python2.7/posixpath.py", line 73, in join
        path += '/' + b
    UnicodeDecodeError: 'ascii' codec can't decode byte 0xe7 in position 22: ordinal not in range(128)
[E 180918 16:42:43 web:2162] 500 GET /favicon.ico (127.0.0.1) 4.03ms
[E 180918 16:48:15 web:1670] Uncaught exception GET /api/imagecode?codeid=123&pcodeid= (127.0.0.1)
    HTTPServerRequest(protocol='http', host='127.0.0.1:8000', method='GET', uri='/api/imagecode?codeid=123&pcodeid=', version='HTTP/1.1', remote_ip='127.0.0.1')
    Traceback (most recent call last):
      File "/usr/local/lib/python2.7/dist-packages/tornado/web.py", line 1590, in _execute
        result = method(*self.path_args, **self.path_kwargs)
      File "/home/phantom/Desktop/爱家租房/handlers/VerifyCode.py", line 21, in get
        name,text,image = captcha.generate_captcha()
    AttributeError: 'module' object has no attribute 'generate_captcha'
[E 180918 16:48:15 web:1114] Uncaught exception in write_error
    Traceback (most recent call last):
      File "/usr/local/lib/python2.7/dist-packages/tornado/web.py", line 1112, in send_error
        self.write_error(status_code, **kwargs)
    TypeError: write_error() takes exactly 1 argument (3 given)
[E 180918 16:48:15 web:2162] 500 GET /api/imagecode?codeid=123&pcodeid= (127.0.0.1) 4.19ms
[E 180918 16:48:25 web:1670] Uncaught exception GET /api/imagecode?codeid=123&pcodeid= (127.0.0.1)
    HTTPServerRequest(protocol='http', host='127.0.0.1:8000', method='GET', uri='/api/imagecode?codeid=123&pcodeid=', version='HTTP/1.1', remote_ip='127.0.0.1')
    Traceback (most recent call last):
      File "/usr/local/lib/python2.7/dist-packages/tornado/web.py", line 1590, in _execute
        result = method(*self.path_args, **self.path_kwargs)
      File "/home/phantom/Desktop/爱家租房/handlers/VerifyCode.py", line 21, in get
        name,text,image = captcha.generate_captcha()
    AttributeError: 'module' object has no attribute 'generate_captcha'
[E 180918 16:48:25 web:1114] Uncaught exception in write_error
    Traceback (most recent call last):
      File "/usr/local/lib/python2.7/dist-packages/tornado/web.py", line 1112, in send_error
        self.write_error(status_code, **kwargs)
    TypeError: write_error() takes exactly 1 argument (3 given)
[E 180918 16:48:25 web:2162] 500 GET /api/imagecode?codeid=123&pcodeid= (127.0.0.1) 7.20ms
[I 180918 17:05:39 autoreload:199] /home/phantom/Desktop/爱家租房/handlers/__init__.py modified; restarting server
[D 180918 17:06:03 PassPort:9] debug msg
[I 180918 17:06:03 PassPort:10] info msg
[W 180918 17:06:03 PassPort:11] warning msg
[E 180918 17:06:03 PassPort:12] error msg
[I 180918 17:06:03 web:2162] 304 GET / (127.0.0.1) 9.32ms
[E 180918 17:06:04 web:1670] Uncaught exception GET /favicon.ico (127.0.0.1)
    HTTPServerRequest(protocol='http', host='127.0.0.1:8000', method='GET', uri='/favicon.ico', version='HTTP/1.1', remote_ip='127.0.0.1')
    Traceback (most recent call last):
      File "/usr/local/lib/python2.7/dist-packages/tornado/web.py", line 1592, in _execute
        result = yield result
      File "/usr/local/lib/python2.7/dist-packages/tornado/gen.py", line 1133, in run
        value = future.result()
      File "/usr/local/lib/python2.7/dist-packages/tornado/concurrent.py", line 261, in result
        raise_exc_info(self._exc_info)
      File "/usr/local/lib/python2.7/dist-packages/tornado/gen.py", line 326, in wrapper
        yielded = next(result)
      File "/usr/local/lib/python2.7/dist-packages/tornado/web.py", line 2463, in get
        absolute_path = self.get_absolute_path(self.root, self.path)
      File "/usr/local/lib/python2.7/dist-packages/tornado/web.py", line 2607, in get_absolute_path
        abspath = os.path.abspath(os.path.join(root, path))
      File "/usr/lib/python2.7/posixpath.py", line 73, in join
        path += '/' + b
    UnicodeDecodeError: 'ascii' codec can't decode byte 0xe7 in position 22: ordinal not in range(128)
[E 180918 17:06:04 web:2162] 500 GET /favicon.ico (127.0.0.1) 15.43ms
[E 180918 17:06:26 web:1670] Uncaught exception GET /register.html (127.0.0.1)
    HTTPServerRequest(protocol='http', host='127.0.0.1:8000', method='GET', uri='/register.html', version='HTTP/1.1', remote_ip='127.0.0.1')
    Traceback (most recent call last):
      File "/usr/local/lib/python2.7/dist-packages/tornado/web.py", line 1592, in _execute
        result = yield result
      File "/usr/local/lib/python2.7/dist-packages/tornado/gen.py", line 1133, in run
        value = future.result()
      File "/usr/local/lib/python2.7/dist-packages/tornado/concurrent.py", line 261, in result
        raise_exc_info(self._exc_info)
      File "/usr/local/lib/python2.7/dist-packages/tornado/gen.py", line 326, in wrapper
        yielded = next(result)
      File "/usr/local/lib/python2.7/dist-packages/tornado/web.py", line 2463, in get
        absolute_path = self.get_absolute_path(self.root, self.path)
      File "/usr/local/lib/python2.7/dist-packages/tornado/web.py", line 2607, in get_absolute_path
        abspath = os.path.abspath(os.path.join(root, path))
      File "/usr/lib/python2.7/posixpath.py", line 73, in join
        path += '/' + b
    UnicodeDecodeError: 'ascii' codec can't decode byte 0xe7 in position 22: ordinal not in range(128)
[E 180918 17:06:26 web:2162] 500 GET /register.html (127.0.0.1) 5.98ms
[E 180918 17:06:26 web:1670] Uncaught exception GET /favicon.ico (127.0.0.1)
    HTTPServerRequest(protocol='http', host='127.0.0.1:8000', method='GET', uri='/favicon.ico', version='HTTP/1.1', remote_ip='127.0.0.1')
    Traceback (most recent call last):
      File "/usr/local/lib/python2.7/dist-packages/tornado/web.py", line 1592, in _execute
        result = yield result
      File "/usr/local/lib/python2.7/dist-packages/tornado/gen.py", line 1133, in run
        value = future.result()
      File "/usr/local/lib/python2.7/dist-packages/tornado/concurrent.py", line 261, in result
        raise_exc_info(self._exc_info)
      File "/usr/local/lib/python2.7/dist-packages/tornado/gen.py", line 326, in wrapper
        yielded = next(result)
      File "/usr/local/lib/python2.7/dist-packages/tornado/web.py", line 2463, in get
        absolute_path = self.get_absolute_path(self.root, self.path)
      File "/usr/local/lib/python2.7/dist-packages/tornado/web.py", line 2607, in get_absolute_path
        abspath = os.path.abspath(os.path.join(root, path))
      File "/usr/lib/python2.7/posixpath.py", line 73, in join
        path += '/' + b
    UnicodeDecodeError: 'ascii' codec can't decode byte 0xe7 in position 22: ordinal not in range(128)
[E 180918 17:06:26 web:2162] 500 GET /favicon.ico (127.0.0.1) 2.88ms
[I 180918 17:14:03 autoreload:199] /home/phantom/Desktop/爱家租房/handlers/BaseHandler.py modified; restarting server
[I 180918 17:15:31 web:2162] 200 GET /register.html (127.0.0.1) 89.34ms
[I 180918 17:15:31 web:2162] 200 GET /static/css/ihome/main.css (127.0.0.1) 2.69ms
[I 180918 17:15:31 web:2162] 200 GET /static/css/ihome/register.css (127.0.0.1) 2.29ms
[I 180918 17:15:31 web:2162] 200 GET /static/images/logo@128x59.png (127.0.0.1) 3.06ms
[I 180918 17:15:31 web:2162] 200 GET /static/js/ihome/register.js (127.0.0.1) 1.96ms
[I 180918 17:15:31 web:2162] 304 GET /static/plugins/bootstrap/css/bootstrap.min.css (127.0.0.1) 3.20ms
[I 180918 17:15:31 web:2162] 304 GET /static/js/jquery.min.js (127.0.0.1) 2.13ms
[I 180918 17:15:31 web:2162] 304 GET /static/plugins/font-awesome/css/font-awesome.min.css (127.0.0.1) 2.04ms
[I 180918 17:15:31 web:2162] 304 GET /static/plugins/bootstrap/js/bootstrap.min.js (127.0.0.1) 2.23ms
[W 180918 17:15:32 web:2162] 404 GET /api/piccode?pcodeid=&codeid=31f084e3-46d0-4611-84d6-83e3ef96729b (127.0.0.1) 6.03ms
[I 180918 17:15:33 web:2162] 200 GET /favicon.ico (127.0.0.1) 3.15ms
[E 180918 17:16:17 web:1670] Uncaught exception GET /api/imagecode?codeid=123&pcodeid= (127.0.0.1)
    HTTPServerRequest(protocol='http', host='127.0.0.1:8000', method='GET', uri='/api/imagecode?codeid=123&pcodeid=', version='HTTP/1.1', remote_ip='127.0.0.1')
    Traceback (most recent call last):
      File "/usr/local/lib/python2.7/dist-packages/tornado/web.py", line 1590, in _execute
        result = method(*self.path_args, **self.path_kwargs)
      File "/home/phantom/Desktop/爱家租房/handlers/VerifyCode.py", line 25, in get
        name,text,image = captcha.generate_captcha()
    AttributeError: 'module' object has no attribute 'generate_captcha'
[E 180918 17:16:17 web:1114] Uncaught exception in write_error
    Traceback (most recent call last):
      File "/usr/local/lib/python2.7/dist-packages/tornado/web.py", line 1112, in send_error
        self.write_error(status_code, **kwargs)
    TypeError: write_error() takes exactly 1 argument (3 given)
[E 180918 17:16:17 web:2162] 500 GET /api/imagecode?codeid=123&pcodeid= (127.0.0.1) 4.66ms
[I 180918 17:18:25 autoreload:199] /home/phantom/Desktop/爱家租房/handlers/__init__.py modified; restarting server
